Workbook
Name Beg_Bal: #REF!
Name Data: #REF!
Name End_Bal: #REF!
Name Extra_Pay: #REF!
Name Full_Print: #REF!
Name Header_Row: ROW(#REF!)
Name Int: #REF!
Name Interest_Rate: #REF!
Name Last_Row: IF(Values_Entered,Header_Row+Number_of_Payments,Header_Row)
Name Loan_Amount: #REF!
Name Loan_Start: #REF!
Name Loan_Years: #REF!
Name Num_Pmt_Per_Year: #REF!
Name Number_of_Payments: MATCH(0.01,End_Bal,-1)+1
Name Pay_Date: #REF!
Name Pay_Num: #REF!
Name Payment_Date: DATE(YEAR(Loan_Start),MONTH(Loan_Start)+payment_number,DAY(Loan_Start))
Name Princ: #REF!
Name Print_Area_Reset: OFFSET(Full_Print,0,0,Last_Row)
Name Sched_Pay: #REF!
Name Scheduled_Extra_Payments: #REF!
Name Scheduled_Interest_Rate: #REF!
Name Scheduled_Monthly_Payment: #REF!
Name Total_Interest: #REF!
Name Total_Pay: #REF!
Name Total_Payment: scheduled_payment+extra_payment
Name Values_Entered: IF(Loan_Amount*Interest_Rate*Loan_Years*Loan_Start>0,1,0)
Name Versements_supplémentaires_facultatifs: #REF!
Name Payment_Date: DATE(YEAR([0]!Loan_Start),MONTH([0]!Loan_Start)+payment_number,DAY([0]!Loan_Start))
Name Total_Payment: scheduled_payment+extra_payment
Name Payment_Date: DATE(YEAR(Loan_Start),MONTH(Loan_Start)+payment_number,DAY(Loan_Start))
Name Total_Payment: scheduled_payment+extra_payment

Sheet Consolidation
A1: Consolidation ******
A3: Date à préciser
A6: Support | B6: ISIN & DIC | C6: Contrat 1 | D6: Contrat 2 | E6: Contrat 3 | F6: Contrat 4 | G6: Contrat 5 | H6: Contrat 6 | I6: Contrat 7 | J6: Contrat 8 | K6: Contrat 9 | L6: Contrat 10 | M6: Contrat 11 | N6: Contrat 12 | O6: Contrat 13 | P6: Contrat 14 | Q6: Contrat 15 | R6: Contrat 16 | S6: Contrat 17 | T6: TOTAL | V6: Risque / 7 | W6: Calcul SRI | X6: Dernière Valeur Liquidative | Z6: Mouvements en cours
C7: =C8+C139+C230+C311+C194+C455+C173+C100 | D7: =D8+D139+D230+D311+D194+D455+D173+D100 | E7: =E8+E139+E230+E311+E194+E455+E173+E100 | F7: =F8+F139+F230+F311+F194+F455+F173+F100 | G7: =G8+G139+G230+G311+G194+G455+G173+G100 | H7: =H8+H139+H230+H311+H194+H455+H173+H100 | I7: =I8+I139+I230+I311+I194+I455+I173+I100 | J7: =J8+J139+J230+J311+J194+J455+J173+J100 | ... S7: =S8+S139+S230+S311+S194+S455+S173+S100 | T7: =SUM(C7:S7) | U7: =+U8+U139+U194+U230+U311+U455+U100+U173 | V7: =W7/T7 | W7: =SUM(W8:W460)
A8: Fonds prudents | C8: =SUM(C9,C23,C43) | D8: =SUM(D9,D23,D43) | E8: =SUM(E9,E23,E43) | F8: =SUM(F9,F23,F43) | G8: =SUM(G9,G23,G43) | H8: =SUM(H9,H23,H43) | I8: =SUM(I9,I23,I43) | J8: =SUM(J9,J23,J43) | ... S8: =SUM(S9,S23,S43) | T8: =SUM(C8:S8) | U8: =U9+U23+U43
A9: Fonds en euro garanti | C9: =SUM(C10:C22) | D9: =SUM(D10:D22) | E9: =SUM(E10:E22) | F9: =SUM(F10:F22) | G9: =SUM(G10:G22) | H9: =SUM(H10:H22) | I9: =SUM(I10:I22) | J9: =SUM(J10:J22) | ... S9: =SUM(S10:S22) | T9: =SUM(C9:S9) | U9: =SUM(U10:U22)
A10: Fonds en euro | B10: / | T10: =SUM(C10:S10) | U10: =T10/T$7 | V10: 1 | W10: =T10*V10
A11: Fonds en euro CARDIF Lux | B11: / | T11: =SUM(C11:S11) | U11: =T11/T$7 | V11: 1 | W11: =T11*V11
A12: Actif Général Generali Vie | B12: / | T12: =SUM(C12:S12) | U12: =T12/T$7 | V12: 1 | W12: =T12*V12
A13: Allianz Fonds Euros | B13: / | T13: =SUM(C13:S13) | U13: =T13/T$7 | V13: 1 | W13: =T13*V13
A14: Fonds en euro Generali Luxembourg | B14: / | T14: =SUM(C14:S14) | U14: =T14/T$7 | V14: 1 | W14: =T14*V14
A15: Apicil Euro Garanti | B15: / | T15: =SUM(C15:S15) | U15: =T15/T$7 | V15: 1 | W15: =T15*V15
A16: Coralis Opportunité | B16: / | T16: =SUM(C16:S16) | U16: =T16/T$7 | V16: 1 | W16: =T16*V16
T17: =SUM(C17:S17) | U17: =T17/T$7 | V17: 1 | W17: =T17*V17
T18: =SUM(C18:S18) | U18: =T18/T$7 | V18: 1 | W18: =T18*V18
T19: =SUM(C19:S19) | U19: =T19/T$7 | V19: 1 | W19: =T19*V19
T20: =SUM(C20:S20) | U20: =T20/T$7 | V20: 1 | W20: =T20*V20
T21: =SUM(C21:S21) | U21: =T21/T$7 | V21: 1 | W21: =T21*V21
T22: =SUM(C22:S22) | U22: =T22/T$7 | V22: 1 | W22: =T22*V22
A23: Fonds monétaires | C23: =SUM(C24:C42) | D23: =SUM(D24:D42) | E23: =SUM(E24:E42) | F23: =SUM(F24:F42) | G23: =SUM(G24:G42) | H23: =SUM(H24:H42) | I23: =SUM(I24:I42) | J23: =SUM(J24:J42) | ... S23: =SUM(S24:S42) | T23: =SUM(C23:S23) | U23: =SUM(U24:U42)
A24: Solde espèces | B24: / | T24: =SUM(C24:S24) | U24: =T24/T$7 | V24: 1 | W24: =T24*V24
A25: BNP Paribas Insticash EUR 1D Short Terme | B25: LU0094219127 | T25: =SUM(C25:S25) | U25: =T25/T$7 | V25: 1 | W25: =T25*V25
A26: BNP Paribas Mois ISR | B26: FR0007009808 | T26: =SUM(C26:S26) | U26: =T26/T$7 | V26: 1 | W26: =T26*V26
A27: Amundi Funds Cash EUR A2 C | B27: LU0568620560 | T27: =SUM(C27:S27) | U27: =T27/T$7 | V27: 1 | W27: =T27*V27
A28: Allianz Securicash SRI I (C) EUR | B28: FR0010017731 | T28: =SUM(C28:S28) | U28: =T28/T$7 | V28: 1 | W28: =T28*V28
A29: SG Monétaire Plus P-C | B29: FR0011362094 | T29: =SUM(C29:S29) | U29: =T29/T$7 | V29: 1 | W29: =T29*V29
A30: SLF (F) Bond ESG 6M | B30: FR0010914358 | T30: =SUM(C30:S30) | U30: =T30/T$7 | V30: 1 | W30: =T30*V30
A31: Generali trésorerie B EUR C | B31: FR0010233726 | T31: =SUM(C31:S31) | U31: =T31/T$7 | V31: 1 | W31: =T31*V31
A32: Apicil Trésorerie P | B32: FR0013328317 | T32: =SUM(C32:S32) | U32: =T32/T$7 | V32: 1 | W32: =T32*V32
A33: AXA Court Terme AC | B33: FR0000288946 | T33: =SUM(C33:S33) | U33: =T33/T$7 | V33: 1 | W33: =T33*V33
A34: Liquidités fonds de fonds | B34: / | T34: =SUM(C34:S34) | U34: =T34/T$7 | V34: 1 | W34: =T34*V34
A35: CIC Union Plus EUR | B35: / | T35: =SUM(C35:S35) | U35: =T35/T$7 | V35: 1 | W35: =T35*V35
A36: Union + TC CAP | B36: / | T36: =SUM(C36:S36) | U36: =T36/T$7 | V36: 1 | W36: =T36*V36
T37: =SUM(C37:S37) | U37: =T37/T$7 | V37: 1 | W37: =T37*V37
T38: =SUM(C38:S38) | U38: =T38/T$7 | V38: 1 | W38: =T38*V38
T39: =SUM(C39:S39) | U39: =T39/T$7 | V39: 1 | W39: =T39*V39
T40: =SUM(C40:S40) | U40: =T40/T$7 | V40: 1 | W40: =T40*V40
T41: =SUM(C41:S41) | U41: =T41/T$7 | V41: 1 | W41: =T41*V41
T42: =SUM(C42:S42) | U42: =T42/T$7 | V42: 1 | W42: =T42*V42
A43: Fonds obligataires | C43: =SUM(C44:C99) | D43: =SUM(D44:D99) | E43: =SUM(E44:E99) | F43: =SUM(F44:F99) | G43: =SUM(G44:G99) | H43: =SUM(H44:H99) | I43: =SUM(I44:I99) | J43: =SUM(J44:J99) | ... S43: =SUM(S44:S99) | T43: =SUM(C43:S43) | U43: =SUM(U44:U99)
...

Sheet Calendrier de sortie
A1: Consolidation ******
A3: Date à préciser
A6: Support | B6: ISIN & DIC | C6: Date d'investissement | D6: Prochain ordre — entrée | E6: Prochain ordre — sortie | F6: Prochaine réception du cash | G6: Pénalité de sortie
A8: Fonds prudents
A9: Fonds en euro garanti
A10: Fonds en euro | B10: / | D10: — | E10: — | F10: — | G10: —
A11: Fonds en euro CARDIF Lux | B11: / | D11: — | E11: — | F11: — | G11: —
A12: Actif Général Generali Vie | B12: / | D12: — | E12: — | F12: — | G12: —
A13: Allianz Fonds Euros | B13: / | D13: — | E13: — | F13: — | G13: —
A14: Fonds en euro Generali Luxembourg | B14: / | D14: — | E14: — | F14: — | G14: —
A15: Apicil Euro Garanti | B15: / | D15: — | E15: — | F15: — | G15: —
A16: Coralis Opportunité | B16: / | D16: — | E16: — | F16: — | G16: —
A23: Fonds monétaires
A24: Solde espèces | B24: / | D24: — | E24: — | F24: — | G24: —
A25: BNP Paribas Insticash EUR 1D Short Terme | B25: LU0094219127 | D25: — | E25: — | F25: — | G25: —
A26: BNP Paribas Mois ISR | B26: FR0007009808 | D26: — | E26: — | F26: — | G26: —
A27: Amundi Funds Cash EUR A2 C | B27: LU0568620560 | D27: — | E27: — | F27: — | G27: —
A28: Allianz Securicash SRI I (C) EUR | B28: FR0010017731 | D28: — | E28: — | F28: — | G28: —
A29: SG Monétaire Plus P-C | B29: FR0011362094 | D29: — | E29: — | F29: — | G29: —
A30: SLF (F) Bond ESG 6M | B30: FR0010914358 | D30: — | E30: — | F30: — | G30: —
A31: Generali trésorerie B EUR C | B31: FR0010233726 | D31: — | E31: — | F31: — | G31: —
A32: Apicil Trésorerie P | B32: FR0013328317 | D32: — | E32: — | F32: — | G32: —
A33: AXA Court Terme AC | B33: FR0000288946 | D33: — | E33: — | F33: — | G33: —
A34: Liquidités fonds de fonds | B34: / | D34: — | E34: — | F34: — | G34: —
A35: CIC Union Plus EUR | B35: / | D35: — | E35: — | F35: — | G35: —
A36: Union + TC CAP | B36: / | D36: — | E36: — | F36: — | G36: —
A43: Fonds obligataires
A44: IVO Emerging Markets Corporate Debt EUR-I | B44: LU1165637460 | D44: — | E44: — | F44: — | G44: —
A45: IVO Emerging Markets Corporate Debt EUR-R | B45: LU1165644672 | D45: — | E45: — | F45: — | G45: —
A46: IVO Emerging Markets Coporate Debt Short Duration SRI EUR | B46: LU2061939646 | D46: — | E46: — | F46: — | G46: —
A47: Ivo Emerging Markets Corporate Debt Short Duration SRI Z | B47: LU2061940222 | D47: — | E47: — | F47: — | G47: —
A48: IVO Emerging Markets Corporate Debt Short Duration SRI R | B48: LU2061939729 | D48: — | E48: — | F48: — | G48: —
A49: IVO IG 2030 I | B49: FR001400SJC8 | D49: — | E49: — | F49: — | G49: —
A50: IVO IG 2030 R | B50: FR001400SJA2 | D50: — | E50: — | F50: — | G50: —
A51: IVO 2028 I | B51: FR001400BJV4 | D51: — | E51: — | F51: — | G51: —
A52: IVO 2028 R | B52: FR001400BJT8 | D52: — | E52: — | F52: — | G52: —
A53: Sycoyield 2030 RC | B53: FR001400MCQ6 | D53: — | E53: — | F53: — | G53: —
A54: Sycoyield 2032 RC | B54: FR0014010IG3 | D54: — | E54: — | F54: — | G54: —
A55: Sycoyield 2026 IC | B55: FR001400A6X2 | D55: — | E55: — | F55: — | G55: —
... A81: Omnibond R | B81: FR0011147594 | D81: — | E81: — | F81: — | G81: —
...

Sheet Consolidation Transparisation
A1: Consolidation transparisée ******
A3: Date à préciser
V5: Transparisation Fonds Althos (30/04/26)
A6: Support | B6: ISIN & DIC | C6: Contrat 1 | D6: Contrat 2 | E6: Contrat 3 | F6: Contrat 4 | G6: Contrat 5 | H6: Contrat 6 | I6: Contrat 7 | J6: Contrat 8 | K6: Contrat 9 | L6: Contrat 10 | M6: Contrat 11 | N6: Contrat 12 | O6: Contrat 13 | P6: Contrat 14 | Q6: Contrat 15 | R6: Contrat 16 | S6: Contrat 17 | T6: TOTAL | V6: Althos Private Equity | X6: Althos Private Credit / Capitalisant | Z6: Althos Private Credit / Distribuant | AB6: Althos Private Infrastructure | AD6: TOTAL | AF6: Risque / 7 | AG6: Calcul SRI
C7: =C8+C139+C230+C311+C194+C455+C173+C100 | D7: =D8+D139+D230+D311+D194+D455+D173+D100 | E7: =E8+E139+E230+E311+E194+E455+E173+E100 | F7: =F8+F139+F230+F311+F194+F455+F173+F100 | G7: =G8+G139+G230+G311+G194+G455+G173+G100 | H7: =H8+H139+H230+H311+H194+H455+H173+H100 | I7: =I8+I139+I230+I311+I194+I455+I173+I100 | J7: =J8+J139+J230+J311+J194+J455+J173+J100 | ... S7: =S8+S139+S230+S311+S194+S455+S173+S100 | T7: =SUM(C7:S7) | U7: =+U8+U139+U194+U230+U311+U455+U100+U173 | V7: =V8+V100+V139+V173+V194+V230+V311+V455 | W7: =W8+W100+W139+W173+W194+W230+W311+W455 | X7: =X8+X100+X139+X173+X194+X230+X311+X455 | Y7: =Y8+Y100+Y139+Y173+Y194+Y230+Y311+Y455 | Z7: =Z8+Z100+Z139+Z173+Z194+Z230+Z311+Z455 | AA7: =AA8+AA100+AA139+AA173+AA194+AA230+AA311+AA455 | AB7: =AB8+AB100+AB139+AB173+AB194+AB230+AB311+AB455 | AC7: =AC8+AC100+AC139+AC173+AC194+AC230+AC311+AC455 | ... AE7: =AE8+AE100+AE139+AE173+AE194+AE230+AE311+AE455 | AF7: =AG7/T7 | AG7: =SUM(AG8:AG460)
A8: Fonds prudents | C8: =SUM(C9,C23,C43) | D8: =SUM(D9,D23,D43) | E8: =SUM(E9,E23,E43) | F8: =SUM(F9,F23,F43) | G8: =SUM(G9,G23,G43) | H8: =SUM(H9,H23,H43) | I8: =SUM(I9,I23,I43) | J8: =SUM(J9,J23,J43) | ... S8: =SUM(S9,S23,S43) | T8: =SUM(C8:S8) | U8: =U9+U23+U43 | V8: =V9+V23+V43 | W8: =W9+W23+W43 | X8: =X9+X23+X43 | Y8: =Y9+Y23+Y43 | Z8: =Z9+Z23+Z43 | AA8: =+AA24 | AB8: =AB9+AB23+AB43 | AC8: =AC9+AC23+AC43 | AD8: =AD9+AD23+AD43 | AE8: =AE9+AE23+AE43
A9: Fonds en euro garanti | C9: =SUM(C10:C22) | D9: =SUM(D10:D22) | E9: =SUM(E10:E22) | F9: =SUM(F10:F22) | G9: =SUM(G10:G22) | H9: =SUM(H10:H22) | I9: =SUM(I10:I22) | J9: =SUM(J10:J22) | ... S9: =SUM(S10:S22) | T9: =SUM(C9:S9) | U9: =SUM(U10:U22) | V9: =SUM(V10:V22) | W9: =SUM(W10:W22) | X9: =SUM(X10:X22) | Y9: =SUM(Y10:Y22) | AB9: =SUM(AB10:AB22) | AC9: =SUM(AC10:AC22) | AD9: =SUM(AD10:AD22) | AE9: =SUM(AE10:AE22)
A10: Fonds en euro | B10: / | T10: =SUM(C10:S10) | U10: =T10/T$7 | AD10: =T10+V10+X10+AB10 | AE10: =AD10/AD$7 | AF10: 1 | AG10: =AD10*AF10
A11: Fonds en euro CARDIF Lux | B11: / | T11: =SUM(C11:S11) | U11: =T11/T$7 | AD11: =T11+V11+X11+AB11 | AE11: =AD11/AD$7 | AF11: 1 | AG11: =AD11*AF11
A12: Actif Général Generali Vie | B12: / | T12: =SUM(C12:S12) | U12: =T12/T$7 | AD12: =T12+V12+X12+AB12 | AE12: =AD12/AD$7 | AF12: 1 | AG12: =AD12*AF12
A13: Allianz Fonds Euros | B13: / | T13: =SUM(C13:S13) | U13: =T13/T$7 | AD13: =T13+V13+X13+AB13 | AE13: =AD13/AD$7 | AF13: 1 | AG13: =AD13*AF13
A14: Fonds en euro Generali Luxembourg | B14: / | T14: =SUM(C14:S14) | U14: =T14/T$7 | AD14: =T14+V14+X14+AB14 | AE14: =AD14/AD$7 | AF14: 1 | AG14: =AD14*AF14
A15: Apicil Euro Garanti | B15: / | T15: =SUM(C15:S15) | U15: =T15/T$7 | AD15: =T15+V15+X15+AB15 | AE15: =AD15/AD$7 | AF15: 1 | AG15: =AD15*AF15
A16: Coralis Opportunité | B16: / | T16: =SUM(C16:S16) | U16: =T16/T$7 | AD16: =T16+V16+X16+AB16 | AE16: =AD16/AD$7 | AF16: 1 | AG16: =AD16*AF16
T17: =SUM(C17:S17) | U17: =T17/T$7 | AD17: =T17+V17+X17+AB17 | AE17: =AD17/AD$7 | AF17: 1 | AG17: =AD17*AF17
T18: =SUM(C18:S18) | U18: =T18/T$7 | AD18: =T18+V18+X18+AB18 | AE18: =AD18/AD$7 | AF18: 1 | AG18: =AD18*AF18
T19: =SUM(C19:S19) | U19: =T19/T$7 | AD19: =T19+V19+X19+AB19 | AE19: =AD19/AD$7 | AF19: 1 | AG19: =AD19*AF19
T20: =SUM(C20:S20) | U20: =T20/T$7 | AD20: =T20+V20+X20+AB20 | AE20: =AD20/AD$7 | AF20: 1 | AG20: =AD20*AF20
T21: =SUM(C21:S21) | U21: =T21/T$7 | AD21: =T21+V21+X21+AB21 | AE21: =AD21/AD$7 | AF21: 1 | AG21: =AD21*AF21
T22: =SUM(C22:S22) | U22: =T22/T$7 | AD22: =T22+V22+X22+AB22 | AE22: =AD22/AD$7 | AF22: 1 | AG22: =AD22*AF22
A23: Fonds monétaires | C23: =SUM(C24:C42) | D23: =SUM(D24:D42) | E23: =SUM(E24:E42) | F23: =SUM(F24:F42) | G23: =SUM(G24:G42) | H23: =SUM(H24:H42) | I23: =SUM(I24:I42) | J23: =SUM(J24:J42) | ... S23: =SUM(S24:S42) | T23: =SUM(C23:S23) | U23: =SUM(U24:U42) | V23: =SUM(V24:V42) | W23: =SUM(W24:W42) | X23: =SUM(X24:X42) | Y23: =SUM(Y24:Y42) | Z23: =SUM(Z24:Z42) | AA23: =SUM(AA24:AA42) | AB23: =SUM(AB24:AB42) | ... AE23: =SUM(AE24:AE42)
A24: Solde espèces | B24: / | T24: =SUM(C24:S24) | U24: =T24/T$7 | V24: =W24*SUM(T$231:T$236) | W24: 0.04 | X24: =Y24*SUM(T195+T197) | Y24: 0.0594 | Z24: =AA24*SUM(T$196+T$198) | AA24: 0.078 | AD24: =T24+V24+X24+AB24+Z24 | AE24: =AD24/AD$7 | AF24: 1 | AG24: =AD24*AF24
A25: BNP Paribas Insticash EUR 1D Short Terme | B25: LU0094219127 | T25: =SUM(C25:S25) | U25: =T25/T$7 | AD25: =T25+V25+X25+AB25+Z25 | AE25: =AD25/AD$7 | AF25: 1 | AG25: =AD25*AF25
A26: BNP Paribas Mois ISR | B26: FR0007009808 | T26: =SUM(C26:S26) | U26: =T26/T$7 | AD26: =T26+V26+X26+AB26+Z26 | AE26: =AD26/AD$7 | AF26: 1 | AG26: =AD26*AF26
A27: Amundi Funds Cash EUR A2 C | B27: LU0568620560 | T27: =SUM(C27:S27) | U27: =T27/T$7 | AD27: =T27+V27+X27+AB27+Z27 | AE27: =AD27/AD$7 | AF27: 1 | AG27: =AD27*AF27
A28: Allianz Securicash SRI I (C) EUR | B28: FR0010017731 | T28: =SUM(C28:S28) | U28: =T28/T$7 | AD28: =T28+V28+X28+AB28+Z28 | AE28: =AD28/AD$7 | AF28: 1 | AG28: =AD28*AF28
A29: SG Monétaire Plus P-C | B29: FR0011362094 | T29: =SUM(C29:S29) | U29: =T29/T$7 | AD29: =T29+V29+X29+AB29+Z29 | AE29: =AD29/AD$7 | AF29: 1 | AG29: =AD29*AF29
A30: SLF (F) Bond ESG 6M | B30: FR0010914358 | T30: =SUM(C30:S30) | U30: =T30/T$7 | AD30: =T30+V30+X30+AB30+Z30 | AE30: =AD30/AD$7 | AF30: 1 | AG30: =AD30*AF30
A31: Generali trésorerie B EUR C | B31: FR0010233726 | T31: =SUM(C31:S31) | U31: =T31/T$7 | AD31: =T31+V31+X31+AB31+Z31 | AE31: =AD31/AD$7 | AF31: 1 | AG31: =AD31*AF31
A32: Apicil Trésorerie P | B32: FR0013328317 | T32: =SUM(C32:S32) | U32: =T32/T$7 | AD32: =T32+V32+X32+AB32+Z32 | AE32: =AD32/AD$7 | AF32: 1 | AG32: =AD32*AF32
A33: AXA Court Terme AC | B33: FR0000288946 | T33: =SUM(C33:S33) | U33: =T33/T$7 | AD33: =T33+V33+X33+AB33+Z33 | AE33: =AD33/AD$7 | AF33: 1 | AG33: =AD33*AF33
A34: Liquidités fonds de fonds | B34: / | T34: =SUM(C34:S34) | U34: =T34/T$7 | AD34: =T34+V34+X34+AB34+Z34 | AE34: =AD34/AD$7 | AF34: 1 | AG34: =AD34*AF34
A35: CIC Union Plus EUR | B35: / | T35: =SUM(C35:S35) | U35: =T35/T$7 | AD35: =T35+V35+X35+AB35+Z35 | AE35: =AD35/AD$7 | AF35: 1 | AG35: =AD35*AF35
A36: Union + TC CAP | B36: / | T36: =SUM(C36:S36) | U36: =T36/T$7 | AD36: =T36+V36+X36+AB36+Z36 | AE36: =AD36/AD$7 | AF36: 1 | AG36: =AD36*AF36
T37: =SUM(C37:S37) | U37: =T37/T$7 | AD37: =T37+V37+X37+AB37+Z37 | AE37: =AD37/AD$7 | AF37: 1 | AG37: =AD37*AF37
T38: =SUM(C38:S38) | U38: =T38/T$7 | AD38: =T38+V38+X38+AB38+Z38 | AE38: =AD38/AD$7 | AF38: 1 | AG38: =AD38*AF38
T39: =SUM(C39:S39) | U39: =T39/T$7 | AD39: =T39+V39+X39+AB39+Z39 | AE39: =AD39/AD$7 | AF39: 1 | AG39: =AD39*AF39
T40: =SUM(C40:S40) | U40: =T40/T$7 | AD40: =T40+V40+X40+AB40+Z40 | AE40: =AD40/AD$7 | AF40: 1 | AG40: =AD40*AF40
T41: =SUM(C41:S41) | U41: =T41/T$7 | AD41: =T41+V41+X41+AB41+Z41 | AE41: =AD41/AD$7 | AF41: 1 | AG41: =AD41*AF41
T42: =SUM(C42:S42) | U42: =T42/T$7 | AD42: =T42+V42+X42+AB42+Z42 | AE42: =AD42/AD$7 | AF42: 1 | AG42: =AD42*AF42
...

Sheet BDD_Calendrier
A1: ISIN | B1: Nom | C1: Type | D1: Cutoff | E1: Valorisation | F1: Execution | G1: PublicationVL | H1: ReglementCash | I1: CleComposite
A2: LU2702161618 | C2: Souscription | D2: 45649 | E2: 45657 | F2: 45658 | G2: 45680 | H2: 45653 | I2: LU2702161618|Souscription|2024-12-23
A3: LU2702161618 | C3: Souscription | D3: 45684 | E3: 45688 | F3: 45689 | G3: 45712 | H3: 45686 | I3: LU2702161618|Souscription|2025-01-27
A4: LU2702161618 | C4: Souscription | D4: 45712 | E4: 45716 | F4: 45717 | G4: 45737 | H4: 45714 | I4: LU2702161618|Souscription|2025-02-24
A5: LU2702161618 | C5: Souscription | D5: 45741 | E5: 45747 | F5: 45748 | G5: 45770 | H5: 45743 | I5: LU2702161618|Souscription|2025-03-25
A6: LU2702161618 | C6: Souscription | D6: 45771 | E6: 45777 | F6: 45778 | G6: 45804 | H6: 45775 | I6: LU2702161618|Souscription|2025-04-24
A7: LU2702161618 | C7: Souscription | D7: 45799 | E7: 45808 | F7: 45809 | G7: 45832 | H7: 45804 | I7: LU2702161618|Souscription|2025-05-22
A8: LU2702161618 | C8: Souscription | D8: 45832 | E8: 45838 | F8: 45839 | G8: 45860 | H8: 45834 | I8: LU2702161618|Souscription|2025-06-24
A9: LU2702161618 | C9: Souscription | D9: 45863 | E9: 45869 | F9: 45870 | G9: 45891 | H9: 45867 | I9: LU2702161618|Souscription|2025-07-25
A10: LU2702161618 | C10: Souscription | D10: 45891 | E10: 45900 | F10: 45901 | G10: 45922 | H10: 45896 | I10: LU2702161618|Souscription|2025-08-22
A11: LU2702161618 | C11: Souscription | D11: 45924 | E11: 45930 | F11: 45931 | G11: 45952 | H11: 45926 | I11: LU2702161618|Souscription|2025-09-24
A12: LU2702161618 | C12: Souscription | D12: 45957 | E12: 45961 | F12: 45962 | G12: 45985 | H12: 45959 | I12: LU2702161618|Souscription|2025-10-27
A13: LU2702161618 | C13: Souscription | D13: 45982 | E13: 45991 | F13: 45992 | G13: 46010 | H13: 45986 | I13: LU2702161618|Souscription|2025-11-21
... A26: LU2702161618 | C26: Rachat | D26: 45992 | E26: 46022 | F26: 46022 | G26: 46043 | H26: 46045 | I26: LU2702161618|Rachat|2025-12-01
A27: LU2605912075 | C27: Souscription | D27: 46048 | F27: 46052 | G27: 46081 | H27: 46051 | I27: LU2605912075|Souscription|2026-01-26
A28: LU2605912075 | C28: Souscription | D28: 46076 | F28: 46080 | G28: 46112 | H28: 46079 | I28: LU2605912075|Souscription|2026-02-23
A29: LU2605912075 | C29: Souscription | D29: 46106 | F29: 46112 | G29: 46142 | H29: 46111 | I29: LU2605912075|Souscription|2026-03-25
A30: LU2605912075 | C30: Souscription | D30: 46136 | F30: 46142 | G30: 46173 | H30: 46141 | I30: LU2605912075|Souscription|2026-04-24
A31: LU2605912075 | C31: Souscription | D31: 46164 | F31: 46171 | G31: 46203 | H31: 46170 | I31: LU2605912075|Souscription|2026-05-22
A32: LU2605912075 | C32: Souscription | D32: 46197 | F32: 46203 | G32: 46234 | H32: 46202 | I32: LU2605912075|Souscription|2026-06-24
A33: LU2605912075 | C33: Souscription | D33: 46230 | F33: 46234 | G33: 46265 | H33: 46233 | I33: LU2605912075|Souscription|2026-07-27
A34: LU2605912075 | C34: Souscription | D34: 46258 | F34: 46262 | G34: 46295 | H34: 46261 | I34: LU2605912075|Souscription|2026-08-24
A35: LU2605912075 | C35: Souscription | D35: 46289 | F35: 46295 | G35: 46326 | H35: 46294 | I35: LU2605912075|Souscription|2026-09-24
A36: LU2605912075 | C36: Souscription | D36: 46321 | F36: 46325 | G36: 46356 | H36: 46324 | I36: LU2605912075|Souscription|2026-10-26
A37: LU2605912075 | C37: Souscription | D37: 46349 | F37: 46356 | G37: 46387 | H37: 46355 | I37: LU2605912075|Souscription|2026-11-23
A38: LU2605912075 | C38: Souscription | D38: 46378 | F38: 46387 | G38: 46418 | H38: 46386 | I38: LU2605912075|Souscription|2026-12-22
A39: LU2605912075 | C39: Rachat | D39: 46024 | F39: 46052 | H39: 46111 | I39: LU2605912075|Rachat|2026-01-02
A40: LU2605912075 | C40: Rachat | D40: 46055 | F40: 46080 | H40: 46141 | I40: LU2605912075|Rachat|2026-02-02
A41: LU2605912075 | C41: Rachat | D41: 46083 | F41: 46112 | H41: 46172 | I41: LU2605912075|Rachat|2026-03-02
A42: LU2605912075 | C42: Rachat | D42: 46113 | F42: 46142 | H42: 46203 | I42: LU2605912075|Rachat|2026-04-01
A43: LU2605912075 | C43: Rachat | D43: 46147 | F43: 46171 | H43: 46233 | I43: LU2605912075|Rachat|2026-05-05
A44: LU2605912075 | C44: Rachat | D44: 46174 | F44: 46203 | H44: 46263 | I44: LU2605912075|Rachat|2026-06-01
A45: LU2605912075 | C45: Rachat | D45: 46204 | F45: 46234 | H45: 46294 | I45: LU2605912075|Rachat|2026-07-01
A46: LU2605912075 | C46: Rachat | D46: 46237 | F46: 46262 | H46: 46325 | I46: LU2605912075|Rachat|2026-08-03
A47: LU2605912075 | C47: Rachat | D47: 46266 | F47: 46295 | H47: 46354 | I47: LU2605912075|Rachat|2026-09-01
A48: LU2605912075 | C48: Rachat | D48: 46296 | F48: 46325 | H48: 46386 | I48: LU2605912075|Rachat|2026-10-01
A49: LU2605912075 | C49: Rachat | D49: 46328 | F49: 46356 | H49: 46416 | I49: LU2605912075|Rachat|2026-11-02
A50: LU2605912075 | C50: Rachat | D50: 46357 | F50: 46387 | H50: 46445 | I50: LU2605912075|Rachat|2026-12-01
A51: LU2860459879 | C51: Souscription | D51: 46038 | E51: 46052 | F51: 46052 | H51: 46052 | I51: LU2860459879|Souscription|2026-01-16
A52: LU2860459879 | C52: Souscription | D52: 46066 | E52: 46080 | F52: 46080 | H52: 46080 | I52: LU2860459879|Souscription|2026-02-13
...

Sheet BDD_Penalites
A1: ISIN | B1: Nom | C1: Kind | D1: Max1 | E1: Rate1 | F1: Max2 | G1: Rate2 | H1: Max3 | I1: Rate3 | J1: Max4 | K1: Rate4 | L1: Rate5 | M1: RawText
A2: FR001400XGO9 | B2: Althos Private Credit part A - Capitalisante | C2: seuil | D2: 12 | E2: 5 | F2: 12 | G2: 0 | H2: 12 | I2: 0 | J2: 12 | K2: 0 | L2: 0 | M2: Pénalité de 5% sur la VL en cas de sortie avant 1 an de détention.
A3: FR001400XGM3 | B3: Althos Private Credit part A - Distribuant | C3: seuil | D3: 12 | E3: 5 | F3: 12 | G3: 0 | H3: 12 | I3: 0 | J3: 12 | K3: 0 | L3: 0 | M3: Pénalité de 5% sur la VL en cas de sortie avant 1 an de détention.
A4: FR001400XGV4 | B4: Althos Private Credit part F - Capitalisante | C4: seuil | D4: 12 | E4: 5 | F4: 12 | G4: 0 | H4: 12 | I4: 0 | J4: 12 | K4: 0 | L4: 0 | M4: Pénalité de 5% sur la VL en cas de sortie avant 1 an de détention.
A5: FR001400XGQ4 | B5: Althos Private Credit part F - Distribuant | C5: seuil | D5: 12 | E5: 5 | F5: 12 | G5: 0 | H5: 12 | I5: 0 | J5: 12 | K5: 0 | L5: 0 | M5: Pénalité de 5% sur la VL en cas de sortie avant 1 an de détention.
A6: LU2702161618 | B6: Ares European Credit Solutions A | C6: seuil | D6: 18 | E6: 5 | F6: 18 | G6: 0 | H6: 18 | I6: 0 | J6: 18 | K6: 0 | L6: 0 | M6: Pénalité de 5% en cas de sortie dans les 18 premiers mois.
A7: LU2702162343 | B7: ARES Strategic Income Fund | C7: inconnue | D7: 0 | E7: 0 | F7: 0 | G7: 0 | H7: 0 | I7: 0 | J7: 0 | K7: 0 | L7: 0
A8: LU3005168235 | B8: AXA IM Private Credit Income Fund S1A EUR | C8: inconnue | D8: 0 | E8: 0 | F8: 0 | G8: 0 | H8: 0 | I8: 0 | J8: 0 | K8: 0 | L8: 0
A9: FR001400L0X2 | B9: Blackstone Crédit Privé Europe SC | C9: seuil | D9: 12 | E9: 2 | F9: 12 | G9: 0 | H9: 12 | I9: 0 | J9: 12 | K9: 0 | L9: 0 | M9: Pénalité de 2% sur la VL en cas de sortie avant 1 an de détention.
A10: LU2480032510 | B10: Blackstone Ecred | C10: inconnue | D10: 0 | E10: 0 | F10: 0 | G10: 0 | H10: 0 | I10: 0 | J10: 0 | K10: 0 | L10: 0
A11: FR0013301546 | B11: FCPR Eurazeo Private Value Europe 3 - part A | C11: aucune | D11: 0 | E11: 0 | F11: 0 | G11: 0 | H11: 0 | I11: 0 | J11: 0 | K11: 0 | L11: 0 | M11: Aucune pénalité actuellement.
A12: FR0013301553 | B12: FCPR Eurazeo Private Value Europe 3 - part C | C12: aucune | D12: 0 | E12: 0 | F12: 0 | G12: 0 | H12: 0 | I12: 0 | J12: 0 | K12: 0 | L12: 0 | M12: Aucune pénalité actuellement.
A13: FR0013301561 | B13: FCPR Eurazeo Private Value Europe 3 - part D | C13: aucune | D13: 0 | E13: 0 | F13: 0 | G13: 0 | H13: 0 | I13: 0 | J13: 0 | K13: 0 | L13: 0 | M13: Aucune pénalité actuellement.
A14: FR001400AZ60 | B14: FCPR SG Tikehau Dette Privée | C14: inconnue | D14: 0 | E14: 0 | F14: 0 | G14: 0 | H14: 0 | I14: 0 | J14: 0 | K14: 0 | L14: 0
A15: FR001400IEE6 | B15: FPS UNI III - Parts A2 | C15: inconnue | D15: 0 | E15: 0 | F15: 0 | G15: 0 | H15: 0 | I15: 0 | J15: 0 | K15: 0 | L15: 0
A16: FR0014001LJ0 | B16: FPS UNIPHARMA II – Parts A | C16: inconnue | D16: 0 | E16: 0 | F16: 0 | G16: 0 | H16: 0 | I16: 0 | J16: 0 | K16: 0 | L16: 0
A17: FR001400NQN1 | B17: GF Lumyna Private Debt Fund | C17: inconnue | D17: 0 | E17: 0 | F17: 0 | G17: 0 | H17: 0 | I17: 0 | J17: 0 | K17: 0 | L17: 0
A18: LU2605912075 | B18: Goldman Sachs European Credit | C18: seuil | D18: 12 | E18: 2 | F18: 12 | G18: 0 | H18: 12 | I18: 0 | J18: 12 | K18: 0 | L18: 0 | M18: Pénalité de 2% acquise au fonds en cas de sortie avant 1 an de détention.
A19: LU2547277330 | B19: Hamilton Lane SCOPE | C19: seuil | D19: 12 | E19: 5 | F19: 12 | G19: 0 | H19: 12 | I19: 0 | J19: 12 | K19: 0 | L19: 0 | M19: Pénalité de 5% de la NAV en cas de rachat dans les 12 premiers mois.
A20: FR001400ZI88 | B20: Morgan Stanley Dette Privée Europe SLP part IA | C20: inconnue | D20: 0 | E20: 0 | F20: 0 | G20: 0 | H20: 0 | I20: 0 | J20: 0 | K20: 0 | L20: 0
A21: LU2860459879 | B21: Morgan Stanley EPIF | C21: inconnue | D21: 0 | E21: 0 | F21: 0 | G21: 0 | H21: 0 | I21: 0 | J21: 0 | K21: 0 | L21: 0
A22: LU3047997575 | B22: Pantheon GCS S Acc | C22: inconnue | D22: 0 | E22: 0 | F22: 0 | G22: 0 | H22: 0 | I22: 0 | J22: 0 | K22: 0 | L22: 0
A23: LU3047997658 | B23: Pantheon GCS S Dis | C23: inconnue | D23: 0 | E23: 0 | F23: 0 | G23: 0 | H23: 0 | I23: 0 | J23: 0 | K23: 0 | L23: 0
A24: LU0672299830 | B24: Cypanga Diversified Portfolio A | C24: inconnue | D24: 0 | E24: 0 | F24: 0 | G24: 0 | H24: 0 | I24: 0 | J24: 0 | K24: 0 | L24: 0
A25: FR0010929794 | B25: H2O Adagio I | C25: inconnue | D25: 0 | E25: 0 | F25: 0 | G25: 0 | H25: 0 | I25: 0 | J25: 0 | K25: 0 | L25: 0
A26: FR0013186772 | B26: H2O Adagio NC | C26: inconnue | D26: 0 | E26: 0 | F26: 0 | G26: 0 | H26: 0 | I26: 0 | J26: 0 | K26: 0 | L26: 0
A27: FR0010923359 | B27: H2O Adagio RC | C27: inconnue | D27: 0 | E27: 0 | F27: 0 | G27: 0 | H27: 0 | I27: 0 | J27: 0 | K27: 0 | L27: 0
A28: FR0013393188 | B28: H2O Adagio SR | C28: inconnue | D28: 0 | E28: 0 | F28: 0 | G28: 0 | H28: 0 | I28: 0 | J28: 0 | K28: 0 | L28: 0
A29: FR0013185196 | B29: H2O Moderato N | C29: inconnue | D29: 0 | E29: 0 | F29: 0 | G29: 0 | H29: 0 | I29: 0 | J29: 0 | K29: 0 | L29: 0
A30: FR0010923367 | B30: H2O Moderato R | C30: inconnue | D30: 0 | E30: 0 | F30: 0 | G30: 0 | H30: 0 | I30: 0 | J30: 0 | K30: 0 | L30: 0
A31: FR0013535242 | B31: H2O Moderato SP N © | C31: inconnue | D31: 0 | E31: 0 | F31: 0 | G31: 0 | H31: 0 | I31: 0 | J31: 0 | K31: 0 | L31: 0
... A51: FR0013324670 | B51: OPPCI PPG Retail B | C51: inconnue | D51: 0 | E51: 0 | F51: 0 | G51: 0 | H51: 0 | I51: 0 | J51: 0 | K51: 0 | L51: 0
A52: LU1346205443 | B52: Partners Group Global Real Estate FCP I | C52: manuel | D52: 0 | E52: 0 | F52: 0 | G52: 0 | H52: 0 | I52: 0 | J52: 0 | K52: 0 | L52: 0 | M52: Pénalité de 4% en cours (au 25/09/2024).
A53: FR0013265683 | B53: PPG Croissance A | C53: inconnue | D53: 0 | E53: 0 | F53: 0 | G53: 0 | H53: 0 | I53: 0 | J53: 0 | K53: 0 | L53: 0
A54: FR001400LW94 | B54: PPG Croissance B | C54: inconnue | D54: 0 | E54: 0 | F54: 0 | G54: 0 | H54: 0 | I54: 0 | J54: 0 | K54: 0 | L54: 0
A55: FR001400C5W4 | B55: PPG Valeur Immo I | C55: inconnue | D55: 0 | E55: 0 | F55: 0 | G55: 0 | H55: 0 | I55: 0 | J55: 0 | K55: 0 | L55: 0
A56: SCPI00004799 | B56: Remake Live | C56: seuil | D56: 60 | E56: 5 | F56: 60 | G56: 0 | H56: 60 | I56: 0 | J56: 60 | K56: 0 | L56: 0 | M56: Pénalité de 5% TTC pour toute sortie anticipée avant 5 ans de détention.
A57: LU2658265710 | B57: Schroder Global Real Estate Total Return | C57: inconnue | D57: 0 | E57: 0 | F57: 0 | G57: 0 | H57: 0 | I57: 0 | J57: 0 | K57: 0 | L57: 0
A58: FR001400E052 | B58: SCPI Remake Live - Part D | C58: seuil | D58: 60 | E58: 5 | F58: 60 | G58: 0 | H58: 60 | I58: 0 | J58: 60 | K58: 0 | L58: 0 | M58: Pénalité de 5% TTC pour toute sortie anticipée avant 5 ans de détention.
A59: FR00140001C5 | B59: SLP June Opportunity | C59: inconnue | D59: 0 | E59: 0 | F59: 0 | G59: 0 | H59: 0 | I59: 0 | J59: 0 | K59: 0 | L59: 0
...
